package edu.utd.minecraft.mod.polycraft.worldgen;

import java.util.Random;

import cpw.mods.fml.common.IWorldGenerator;
import net.minecraft.block.Block;
import net.minecraft.init.Blocks;
import net.minecraft.world.World;
import net.minecraft.world.chunk.IChunkProvider;
import net.minecraft.world.gen.feature.WorldGenerator;

public class StructureTest extends WorldGenerator implements IWorldGenerator {
	protected Block[] getValidSpawnBlocks() {
		return new Block[] { Blocks.grass, Blocks.cobblestone, Blocks.dirt, Blocks.stone, Blocks.sand };
	}

	public boolean locationIsValidSpawn(World world, int i, int j, int k) {
		int distanceToAir = 0;
		Block check = world.getBlock(i, j, k);

		while (check != Blocks.air) {
			if (distanceToAir > 2) {
				return false;
			}

			distanceToAir++;
			check = world.getBlock(i, j + distanceToAir, k);
		}

		j += distanceToAir - 1;

		Block block = world.getBlock(i, j, k);
		Block blockAbove = world.getBlock(i, j + 1, k);
		Block blockBelow = world.getBlock(i, j - 1, k);

		for (Block x : getValidSpawnBlocks()) {
			if (blockAbove != Blocks.air) {
				return false;
			}
			if (block == x) {
				return true;
			} else if ((block == Blocks.snow || block == Blocks.tallgrass) && blockBelow == x) {
				return true;
			}
		}

		return false;
	}

	public StructureTest() {
	}

	@Override
	public void generate(Random random, int chunkX, int chunkZ, World world, IChunkProvider chunkGenerator,
			IChunkProvider chunkProvider) {
		System.out.println("test chunk generate");
		this.generate(world, random, chunkX * 16 + random.nextInt(16), 64 + random.nextInt(32), chunkZ * 16 + random.nextInt(16));
	}

	public void setBlock(World world, int x, int y, int z, Block block, int metadata) {
		Block b1 = world.getBlock(x, y, z);

		if (b1.isAir(world, x, y, z) || b1.isLeaves(world, x, y, z) || b1.isFoliage(world, x, y, z)) {
			world.setBlock(x, y, z, block, metadata, 2);
		}
	}

	@Override
	public boolean generate(World world, Random rand, int i, int j, int k) {
		// check that each corner is one of the valid spawn blocks
		System.out.println("test pos generate");
		if (!locationIsValidSpawn(world, i, j, k) || !locationIsValidSpawn(world, i + 12, j, k)
				|| !locationIsValidSpawn(world, i + 12, j, k + 6) || !locationIsValidSpawn(world, i, j, k + 6)) {
			System.out.printf("Invalid location %d %d %d\n", i, j, k);
			return false;
		}
		System.out.printf("Generate at location %d %d %d\n", i, j, k);

		k = k - 10;
		i = i - 10;

		this.setBlock(world, i + 0, j + 4, k + 0, Blocks.air, 3);
		this.setBlock(world, i + 0, j + 4, k + 1, Blocks.air, 3);
		this.setBlock(world, i + 0, j + 4, k + 2, Blocks.air, 3);
		this.setBlock(world, i + 0, j + 4, k + 3, Blocks.air, 3);
		this.setBlock(world, i + 0, j + 4, k + 4, Blocks.air, 3);
		this.setBlock(world, i + 0, j + 4, k + 5, Blocks.air, 3);
		this.setBlock(world, i + 0, j + 4, k + 6, Blocks.air, 3);
		this.setBlock(world, i + 0, j + 5, k + 0, Blocks.air, 3);
		this.setBlock(world, i + 0, j + 5, k + 1, Blocks.air, 3);
		this.setBlock(world, i + 0, j + 5, k + 2, Blocks.air, 3);
		this.setBlock(world, i + 0, j + 5, k + 3, Blocks.air, 3);
		this.setBlock(world, i + 0, j + 5, k + 4, Blocks.air, 3);
		this.setBlock(world, i + 0, j + 5, k + 5, Blocks.air, 3);
		this.setBlock(world, i + 0, j + 5, k + 6, Blocks.air, 3);
		this.setBlock(world, i + 0, j + 6, k + 1, Blocks.air, 11);
		this.setBlock(world, i + 0, j + 6, k + 2, Blocks.air, 11);
		this.setBlock(world, i + 0, j + 6, k + 3, Blocks.air, 11);
		this.setBlock(world, i + 0, j + 6, k + 4, Blocks.air, 11);
		this.setBlock(world, i + 0, j + 6, k + 5, Blocks.air, 11);
		this.setBlock(world, i + 0, j + 6, k + 6, Blocks.air, 11);
		this.setBlock(world, i + 1, j + 0, k + 1, Blocks.cobblestone, 0);
		this.setBlock(world, i + 1, j + 0, k + 2, Blocks.cobblestone, 0);
		this.setBlock(world, i + 1, j + 0, k + 3, Blocks.cobblestone, 0);
		this.setBlock(world, i + 1, j + 0, k + 4, Blocks.cobblestone, 0);
		this.setBlock(world, i + 1, j + 0, k + 5, Blocks.cobblestone, 0);
		this.setBlock(world, i + 1, j + 0, k + 6, Blocks.cobblestone, 0);
		this.setBlock(world, i + 1, j + 1, k + 1, Blocks.sandstone, 0);
		this.setBlock(world, i + 1, j + 1, k + 2, Blocks.sandstone, 0);
		this.setBlock(world, i + 1, j + 1, k + 3, Blocks.sandstone, 0);
		this.setBlock(world, i + 1, j + 1, k + 4, Blocks.sandstone, 0);
		this.setBlock(world, i + 1, j + 1, k + 5, Blocks.sandstone, 0);
		this.setBlock(world, i + 1, j + 1, k + 6, Blocks.sandstone, 0);
		this.setBlock(world, i + 1, j + 2, k + 1, Blocks.sandstone, 0);
		this.setBlock(world, i + 1, j + 2, k + 2, Blocks.sandstone, 0);
		this.setBlock(world, i + 1, j + 2, k + 3, Blocks.sandstone, 0);
		this.setBlock(world, i + 1, j + 2, k + 4, Blocks.sandstone, 0);
		this.setBlock(world, i + 1, j + 2, k + 5, Blocks.sandstone, 0);
		this.setBlock(world, i + 1, j + 2, k + 6, Blocks.sandstone, 0);
		this.setBlock(world, i + 1, j + 3, k + 1, Blocks.sandstone, 0);
		this.setBlock(world, i + 1, j + 3, k + 2, Blocks.sandstone, 0);
		this.setBlock(world, i + 1, j + 3, k + 3, Blocks.sandstone, 0);
		this.setBlock(world, i + 1, j + 3, k + 4, Blocks.sandstone, 0);
		this.setBlock(world, i + 1, j + 3, k + 5, Blocks.sandstone, 0);
		this.setBlock(world, i + 1, j + 3, k + 6, Blocks.sandstone, 0);
		this.setBlock(world, i + 1, j + 4, k + 1, Blocks.sandstone, 0);
		this.setBlock(world, i + 1, j + 4, k + 2, Blocks.sandstone, 0);
		this.setBlock(world, i + 1, j + 4, k + 3, Blocks.sandstone, 0);
		this.setBlock(world, i + 1, j + 4, k + 4, Blocks.sandstone, 0);
		this.setBlock(world, i + 1, j + 4, k + 5, Blocks.sandstone, 0);
		this.setBlock(world, i + 1, j + 4, k + 6, Blocks.sandstone, 0);
		this.setBlock(world, i + 1, j + 5, k + 1, Blocks.sandstone, 0);
		this.setBlock(world, i + 1, j + 5, k + 2, Blocks.sandstone, 0);
		this.setBlock(world, i + 1, j + 5, k + 3, Blocks.sandstone, 0);
		this.setBlock(world, i + 1, j + 5, k + 4, Blocks.sandstone, 0);
		this.setBlock(world, i + 1, j + 5, k + 5, Blocks.sandstone, 0);
		this.setBlock(world, i + 1, j + 5, k + 6, Blocks.sandstone, 0);
		this.setBlock(world, i + 1, j + 6, k + 0, Blocks.air, 3);
		this.setBlock(world, i + 1, j + 6, k + 1, Blocks.air, 3);
		this.setBlock(world, i + 1, j + 6, k + 2, Blocks.air, 3);
		this.setBlock(world, i + 1, j + 6, k + 3, Blocks.air, 3);
		this.setBlock(world, i + 1, j + 6, k + 4, Blocks.air, 3);
		this.setBlock(world, i + 1, j + 6, k + 5, Blocks.air, 3);
		this.setBlock(world, i + 1, j + 6, k + 6, Blocks.air, 3);
		this.setBlock(world, i + 1, j + 7, k + 0, Blocks.air, 3);
		this.setBlock(world, i + 1, j + 7, k + 1, Blocks.air, 3);
		this.setBlock(world, i + 1, j + 7, k + 2, Blocks.air, 3);
		this.setBlock(world, i + 1, j + 7, k + 3, Blocks.air, 3);
		this.setBlock(world, i + 1, j + 7, k + 4, Blocks.air, 3);
		this.setBlock(world, i + 1, j + 7, k + 5, Blocks.air, 3);
		this.setBlock(world, i + 1, j + 7, k + 6, Blocks.air, 3);
		this.setBlock(world, i + 1, j + 8, k + 1, Blocks.air, 11);
		this.setBlock(world, i + 1, j + 8, k + 2, Blocks.air, 11);
		this.setBlock(world, i + 1, j + 8, k + 3, Blocks.air, 11);
		this.setBlock(world, i + 1, j + 8, k + 4, Blocks.air, 11);
		this.setBlock(world, i + 1, j + 8, k + 5, Blocks.air, 11);
		this.setBlock(world, i + 1, j + 8, k + 6, Blocks.air, 11);
		this.setBlock(world, i + 2, j + 0, k + 1, Blocks.cobblestone, 0);
		this.setBlock(world, i + 2, j + 0, k + 2, Blocks.cobblestone, 0);
		this.setBlock(world, i + 2, j + 0, k + 3, Blocks.cobblestone, 0);
		this.setBlock(world, i + 2, j + 0, k + 4, Blocks.cobblestone, 0);
		this.setBlock(world, i + 2, j + 0, k + 5, Blocks.cobblestone, 0);
		this.setBlock(world, i + 2, j + 0, k + 6, Blocks.cobblestone, 0);
		this.setBlock(world, i + 2, j + 1, k + 1, Blocks.sandstone, 0);
		this.setBlock(world, i + 2, j + 1, k + 2, Blocks.jukebox, 1);
		this.setBlock(world, i + 2, j + 2, k + 1, Blocks.planks, 1);
		this.setBlock(world, i + 2, j + 3, k + 1, Blocks.planks, 1);
		this.setBlock(world, i + 2, j + 4, k + 1, Blocks.sandstone, 0);
		this.setBlock(world, i + 2, j + 5, k + 1, Blocks.sandstone, 0);
		this.setBlock(world, i + 2, j + 5, k + 2, Blocks.planks, 1);
		this.setBlock(world, i + 2, j + 5, k + 3, Blocks.planks, 1);
		this.setBlock(world, i + 2, j + 5, k + 4, Blocks.planks, 1);
		this.setBlock(world, i + 2, j + 5, k + 5, Blocks.planks, 1);
		this.setBlock(world, i + 2, j + 5, k + 6, Blocks.planks, 1);
		this.setBlock(world, i + 2, j + 6, k + 1, Blocks.planks, 1);
		this.setBlock(world, i + 2, j + 6, k + 2, Blocks.planks, 1);
		this.setBlock(world, i + 2, j + 6, k + 3, Blocks.planks, 1);
		this.setBlock(world, i + 2, j + 6, k + 4, Blocks.planks, 1);
		this.setBlock(world, i + 2, j + 6, k + 5, Blocks.planks, 1);
		this.setBlock(world, i + 2, j + 6, k + 6, Blocks.planks, 1);
		this.setBlock(world, i + 2, j + 7, k + 1, Blocks.log, 2);
		this.setBlock(world, i + 2, j + 7, k + 2, Blocks.planks, 1);
		this.setBlock(world, i + 2, j + 7, k + 3, Blocks.planks, 1);
		this.setBlock(world, i + 2, j + 7, k + 4, Blocks.planks, 1);
		this.setBlock(world, i + 2, j + 7, k + 5, Blocks.planks, 1);
		this.setBlock(world, i + 2, j + 7, k + 6, Blocks.planks, 1);
		this.setBlock(world, i + 2, j + 8, k + 0, Blocks.air, 3);
		this.setBlock(world, i + 2, j + 8, k + 1, Blocks.air, 3);
		this.setBlock(world, i + 2, j + 8, k + 2, Blocks.air, 3);
		this.setBlock(world, i + 2, j + 8, k + 3, Blocks.air, 3);
		this.setBlock(world, i + 2, j + 8, k + 4, Blocks.air, 3);
		this.setBlock(world, i + 2, j + 8, k + 5, Blocks.air, 3);
		this.setBlock(world, i + 2, j + 8, k + 6, Blocks.air, 3);
		this.setBlock(world, i + 2, j + 9, k + 0, Blocks.air, 3);
		this.setBlock(world, i + 2, j + 9, k + 1, Blocks.air, 3);
		this.setBlock(world, i + 2, j + 9, k + 2, Blocks.air, 3);
		this.setBlock(world, i + 2, j + 9, k + 3, Blocks.air, 3);
		this.setBlock(world, i + 2, j + 9, k + 4, Blocks.air, 3);
		this.setBlock(world, i + 2, j + 9, k + 5, Blocks.air, 3);
		this.setBlock(world, i + 2, j + 9, k + 6, Blocks.air, 3);
		this.setBlock(world, i + 2, j + 10, k + 1, Blocks.air, 11);
		this.setBlock(world, i + 2, j + 10, k + 2, Blocks.air, 11);
		this.setBlock(world, i + 2, j + 10, k + 3, Blocks.air, 11);
		this.setBlock(world, i + 2, j + 10, k + 4, Blocks.air, 11);
		this.setBlock(world, i + 2, j + 10, k + 5, Blocks.air, 11);
		this.setBlock(world, i + 2, j + 10, k + 6, Blocks.air, 11);
		this.setBlock(world, i + 3, j + 0, k + 1, Blocks.cobblestone, 0);
		this.setBlock(world, i + 3, j + 0, k + 2, Blocks.cobblestone, 0);
		this.setBlock(world, i + 3, j + 0, k + 3, Blocks.cobblestone, 0);
		this.setBlock(world, i + 3, j + 0, k + 4, Blocks.cobblestone, 0);
		this.setBlock(world, i + 3, j + 0, k + 5, Blocks.cobblestone, 0);
		this.setBlock(world, i + 3, j + 0, k + 6, Blocks.cobblestone, 0);
		this.setBlock(world, i + 3, j + 1, k + 1, Blocks.sandstone, 0);
		this.setBlock(world, i + 3, j + 1, k + 2, Blocks.crafting_table, 0);
		this.setBlock(world, i + 3, j + 2, k + 1, Blocks.air, 12);
		this.setBlock(world, i + 3, j + 3, k + 1, Blocks.air, 12);
		this.setBlock(world, i + 3, j + 4, k + 1, Blocks.sandstone, 0);
		this.setBlock(world, i + 3, j + 5, k + 1, Blocks.sandstone, 0);
		this.setBlock(world, i + 3, j + 5, k + 2, Blocks.planks, 1);
		this.setBlock(world, i + 3, j + 5, k + 3, Blocks.planks, 1);
		this.setBlock(world, i + 3, j + 5, k + 4, Blocks.planks, 1);
		this.setBlock(world, i + 3, j + 5, k + 5, Blocks.planks, 1);
		this.setBlock(world, i + 3, j + 5, k + 6, Blocks.planks, 1);
		this.setBlock(world, i + 3, j + 6, k + 0, Blocks.air, 3);
		this.setBlock(world, i + 3, j + 6, k + 1, Blocks.planks, 1);
		this.setBlock(world, i + 3, j + 7, k + 1, Blocks.planks, 1);
		this.setBlock(world, i + 3, j + 8, k + 1, Blocks.planks, 1);
		this.setBlock(world, i + 3, j + 8, k + 2, Blocks.planks, 1);
		this.setBlock(world, i + 3, j + 8, k + 3, Blocks.planks, 1);
		this.setBlock(world, i + 3, j + 8, k + 4, Blocks.planks, 1);
		this.setBlock(world, i + 3, j + 8, k + 5, Blocks.planks, 1);
		this.setBlock(world, i + 3, j + 8, k + 6, Blocks.planks, 1);
		this.setBlock(world, i + 3, j + 9, k + 1, Blocks.planks, 5);
		this.setBlock(world, i + 3, j + 9, k + 2, Blocks.planks, 1);
		this.setBlock(world, i + 3, j + 9, k + 3, Blocks.planks, 1);
		this.setBlock(world, i + 3, j + 9, k + 4, Blocks.planks, 1);
		this.setBlock(world, i + 3, j + 9, k + 5, Blocks.planks, 1);
		this.setBlock(world, i + 3, j + 9, k + 6, Blocks.planks, 1);
		this.setBlock(world, i + 3, j + 10, k + 0, Blocks.air, 3);
		this.setBlock(world, i + 3, j + 10, k + 1, Blocks.air, 3);
		this.setBlock(world, i + 3, j + 10, k + 2, Blocks.air, 3);
		this.setBlock(world, i + 3, j + 10, k + 3, Blocks.air, 3);
		this.setBlock(world, i + 3, j + 10, k + 4, Blocks.air, 3);
		this.setBlock(world, i + 3, j + 10, k + 5, Blocks.air, 3);
		this.setBlock(world, i + 3, j + 10, k + 6, Blocks.air, 3);
		this.setBlock(world, i + 3, j + 11, k + 0, Blocks.air, 3);
		this.setBlock(world, i + 3, j + 11, k + 1, Blocks.air, 3);
		this.setBlock(world, i + 3, j + 11, k + 2, Blocks.air, 3);
		this.setBlock(world, i + 3, j + 11, k + 3, Blocks.air, 3);
		this.setBlock(world, i + 3, j + 11, k + 4, Blocks.air, 3);
		this.setBlock(world, i + 3, j + 11, k + 5, Blocks.air, 3);
		this.setBlock(world, i + 3, j + 11, k + 6, Blocks.air, 3);
		this.setBlock(world, i + 3, j + 12, k + 1, Blocks.air, 11);
		this.setBlock(world, i + 3, j + 12, k + 2, Blocks.air, 11);
		this.setBlock(world, i + 3, j + 12, k + 3, Blocks.air, 11);
		this.setBlock(world, i + 3, j + 12, k + 4, Blocks.air, 11);
		this.setBlock(world, i + 3, j + 12, k + 5, Blocks.air, 11);
		this.setBlock(world, i + 3, j + 12, k + 6, Blocks.air, 11);
		this.setBlock(world, i + 4, j + 0, k + 1, Blocks.cobblestone, 0);
		this.setBlock(world, i + 4, j + 0, k + 2, Blocks.cobblestone, 0);
		this.setBlock(world, i + 4, j + 0, k + 3, Blocks.cobblestone, 0);
		this.setBlock(world, i + 4, j + 0, k + 4, Blocks.cobblestone, 0);
		this.setBlock(world, i + 4, j + 0, k + 5, Blocks.cobblestone, 0);
		this.setBlock(world, i + 4, j + 0, k + 6, Blocks.cobblestone, 0);
		this.setBlock(world, i + 4, j + 1, k + 1, Blocks.sandstone, 0);
		this.setBlock(world, i + 4, j + 2, k + 1, Blocks.planks, 1);
		this.setBlock(world, i + 4, j + 3, k + 1, Blocks.planks, 1);
		this.setBlock(world, i + 4, j + 4, k + 1, Blocks.sandstone, 0);
		this.setBlock(world, i + 4, j + 5, k + 1, Blocks.sandstone, 0);
		this.setBlock(world, i + 4, j + 5, k + 2, Blocks.planks, 1);
		this.setBlock(world, i + 4, j + 5, k + 3, Blocks.planks, 1);
		this.setBlock(world, i + 4, j + 5, k + 4, Blocks.planks, 1);
		this.setBlock(world, i + 4, j + 5, k + 5, Blocks.lit_redstone_lamp, 0);
		this.setBlock(world, i + 4, j + 5, k + 6, Blocks.planks, 1);
		this.setBlock(world, i + 4, j + 6, k + 0, Blocks.air, 3);
		this.setBlock(world, i + 4, j + 6, k + 1, Blocks.planks, 1);
		this.setBlock(world, i + 4, j + 7, k + 1, Blocks.log, 2);
		this.setBlock(world, i + 4, j + 8, k + 1, Blocks.log, 2);
		this.setBlock(world, i + 4, j + 9, k + 1, Blocks.planks, 1);
		this.setBlock(world, i + 4, j + 10, k + 1, Blocks.log, 2);
		this.setBlock(world, i + 4, j + 10, k + 2, Blocks.planks, 1);
		this.setBlock(world, i + 4, j + 10, k + 3, Blocks.planks, 1);
		this.setBlock(world, i + 4, j + 10, k + 4, Blocks.planks, 1);
		this.setBlock(world, i + 4, j + 10, k + 5, Blocks.planks, 1);
		this.setBlock(world, i + 4, j + 10, k + 6, Blocks.planks, 1);
		this.setBlock(world, i + 4, j + 11, k + 1, Blocks.log, 2);
		this.setBlock(world, i + 4, j + 11, k + 2, Blocks.planks, 1);
		this.setBlock(world, i + 4, j + 11, k + 3, Blocks.planks, 1);
		this.setBlock(world, i + 4, j + 11, k + 4, Blocks.planks, 1);
		this.setBlock(world, i + 4, j + 11, k + 5, Blocks.planks, 1);
		this.setBlock(world, i + 4, j + 11, k + 6, Blocks.planks, 1);
		this.setBlock(world, i + 4, j + 12, k + 0, Blocks.air, 3);
		this.setBlock(world, i + 4, j + 12, k + 1, Blocks.air, 3);
		this.setBlock(world, i + 4, j + 12, k + 2, Blocks.air, 3);
		this.setBlock(world, i + 4, j + 12, k + 3, Blocks.air, 3);
		this.setBlock(world, i + 4, j + 12, k + 4, Blocks.air, 3);
		this.setBlock(world, i + 4, j + 12, k + 5, Blocks.air, 3);
		this.setBlock(world, i + 4, j + 12, k + 6, Blocks.air, 3);
		this.setBlock(world, i + 4, j + 13, k + 0, Blocks.air, 3);
		this.setBlock(world, i + 4, j + 13, k + 1, Blocks.air, 3);
		this.setBlock(world, i + 4, j + 13, k + 2, Blocks.air, 3);
		this.setBlock(world, i + 4, j + 13, k + 3, Blocks.air, 3);
		this.setBlock(world, i + 4, j + 13, k + 4, Blocks.air, 3);
		this.setBlock(world, i + 4, j + 13, k + 5, Blocks.air, 3);
		this.setBlock(world, i + 4, j + 13, k + 6, Blocks.air, 3);
		this.setBlock(world, i + 4, j + 14, k + 1, Blocks.air, 11);
		this.setBlock(world, i + 4, j + 14, k + 2, Blocks.air, 11);
		this.setBlock(world, i + 4, j + 14, k + 3, Blocks.air, 11);
		this.setBlock(world, i + 4, j + 14, k + 4, Blocks.air, 11);
		this.setBlock(world, i + 4, j + 14, k + 5, Blocks.air, 11);
		this.setBlock(world, i + 4, j + 14, k + 6, Blocks.air, 11);
		this.setBlock(world, i + 5, j + 0, k + 1, Blocks.cobblestone, 0);
		this.setBlock(world, i + 5, j + 0, k + 2, Blocks.cobblestone, 0);
		this.setBlock(world, i + 5, j + 0, k + 3, Blocks.cobblestone, 0);
		this.setBlock(world, i + 5, j + 0, k + 4, Blocks.cobblestone, 0);
		this.setBlock(world, i + 5, j + 0, k + 5, Blocks.cobblestone, 0);
		this.setBlock(world, i + 5, j + 0, k + 6, Blocks.cobblestone, 0);
		this.setBlock(world, i + 5, j + 1, k + 1, Blocks.sandstone, 0);
		this.setBlock(world, i + 5, j + 2, k + 1, Blocks.sandstone, 0);
		this.setBlock(world, i + 5, j + 3, k + 1, Blocks.sandstone, 0);
		this.setBlock(world, i + 5, j + 4, k + 1, Blocks.sandstone, 0);
		this.setBlock(world, i + 5, j + 5, k + 1, Blocks.sandstone, 0);
		this.setBlock(world, i + 5, j + 5, k + 2, Blocks.planks, 1);
		this.setBlock(world, i + 5, j + 5, k + 3, Blocks.planks, 1);
		this.setBlock(world, i + 5, j + 5, k + 4, Blocks.planks, 1);
		this.setBlock(world, i + 5, j + 5, k + 5, Blocks.planks, 1);
		this.setBlock(world, i + 5, j + 5, k + 6, Blocks.planks, 1);
		this.setBlock(world, i + 5, j + 6, k + 0, Blocks.air, 3);
		this.setBlock(world, i + 5, j + 6, k + 1, Blocks.planks, 1);
		this.setBlock(world, i + 5, j + 7, k + 1, Blocks.log, 2);
		this.setBlock(world, i + 5, j + 8, k + 1, Blocks.log, 2);
		this.setBlock(world, i + 5, j + 9, k + 1, Blocks.planks, 1);
		this.setBlock(world, i + 5, j + 10, k + 1, Blocks.log, 2);
		this.setBlock(world, i + 5, j + 11, k + 1, Blocks.log, 2);
		this.setBlock(world, i + 5, j + 12, k + 1, Blocks.planks, 1);
		this.setBlock(world, i + 5, j + 12, k + 2, Blocks.planks, 1);
		this.setBlock(world, i + 5, j + 12, k + 3, Blocks.planks, 1);
		this.setBlock(world, i + 5, j + 12, k + 4, Blocks.planks, 1);
		this.setBlock(world, i + 5, j + 12, k + 5, Blocks.planks, 1);
		this.setBlock(world, i + 5, j + 12, k + 6, Blocks.planks, 1);
		this.setBlock(world, i + 5, j + 13, k + 1, Blocks.log, 2);
		this.setBlock(world, i + 5, j + 13, k + 2, Blocks.planks, 1);
		this.setBlock(world, i + 5, j + 13, k + 3, Blocks.planks, 1);
		this.setBlock(world, i + 5, j + 13, k + 4, Blocks.planks, 1);
		this.setBlock(world, i + 5, j + 13, k + 5, Blocks.planks, 1);
		this.setBlock(world, i + 5, j + 13, k + 6, Blocks.planks, 1);
		this.setBlock(world, i + 5, j + 14, k + 0, Blocks.air, 3);
		this.setBlock(world, i + 5, j + 14, k + 1, Blocks.air, 3);
		this.setBlock(world, i + 5, j + 14, k + 2, Blocks.air, 3);
		this.setBlock(world, i + 5, j + 14, k + 3, Blocks.air, 3);
		this.setBlock(world, i + 5, j + 14, k + 4, Blocks.air, 3);
		this.setBlock(world, i + 5, j + 14, k + 5, Blocks.air, 3);
		this.setBlock(world, i + 5, j + 14, k + 6, Blocks.air, 3);
		this.setBlock(world, i + 6, j + 0, k + 1, Blocks.cobblestone, 0);
		this.setBlock(world, i + 6, j + 0, k + 2, Blocks.cobblestone, 0);
		this.setBlock(world, i + 6, j + 0, k + 3, Blocks.cobblestone, 0);
		this.setBlock(world, i + 6, j + 0, k + 4, Blocks.cobblestone, 0);
		this.setBlock(world, i + 6, j + 0, k + 5, Blocks.cobblestone, 0);
		this.setBlock(world, i + 6, j + 0, k + 6, Blocks.cobblestone, 0);
		this.setBlock(world, i + 6, j + 1, k + 1, Blocks.planks, 1);
		this.setBlock(world, i + 6, j + 2, k + 1, Blocks.planks, 1);
		this.setBlock(world, i + 6, j + 3, k + 1, Blocks.planks, 1);
		this.setBlock(world, i + 6, j + 4, k + 1, Blocks.planks, 1);
		this.setBlock(world, i + 6, j + 4, k + 6, Blocks.planks, 1);
		this.setBlock(world, i + 6, j + 5, k + 1, Blocks.planks, 1);
		this.setBlock(world, i + 6, j + 5, k + 2, Blocks.planks, 1);
		this.setBlock(world, i + 6, j + 5, k + 3, Blocks.planks, 1);
		this.setBlock(world, i + 6, j + 5, k + 4, Blocks.planks, 1);
		this.setBlock(world, i + 6, j + 5, k + 5, Blocks.planks, 1);
		this.setBlock(world, i + 6, j + 5, k + 6, Blocks.planks, 1);
		this.setBlock(world, i + 6, j + 6, k + 0, Blocks.air, 3);
		this.setBlock(world, i + 6, j + 6, k + 1, Blocks.planks, 1);
		this.setBlock(world, i + 6, j + 7, k + 1, Blocks.planks, 1);
		this.setBlock(world, i + 6, j + 8, k + 1, Blocks.planks, 1);
		this.setBlock(world, i + 6, j + 9, k + 1, Blocks.planks, 5);
		this.setBlock(world, i + 6, j + 10, k + 1, Blocks.planks, 1);
		this.setBlock(world, i + 6, j + 11, k + 1, Blocks.planks, 1);
		this.setBlock(world, i + 6, j + 12, k + 1, Blocks.planks, 5);
		this.setBlock(world, i + 6, j + 13, k + 1, Blocks.planks, 1);
		this.setBlock(world, i + 6, j + 14, k + 0, Blocks.nether_brick_fence, 0);
		this.setBlock(world, i + 6, j + 14, k + 1, Blocks.log, 2);
		this.setBlock(world, i + 6, j + 14, k + 2, Blocks.planks, 1);
		this.setBlock(world, i + 6, j + 14, k + 3, Blocks.planks, 1);
		this.setBlock(world, i + 6, j + 14, k + 4, Blocks.planks, 1);
		this.setBlock(world, i + 6, j + 14, k + 5, Blocks.planks, 1);
		this.setBlock(world, i + 6, j + 14, k + 6, Blocks.planks, 1);
		this.setBlock(world, i + 6, j + 15, k + 0, Blocks.air, 3);
		this.setBlock(world, i + 6, j + 15, k + 1, Blocks.air, 3);
		this.setBlock(world, i + 6, j + 15, k + 2, Blocks.air, 3);
		this.setBlock(world, i + 6, j + 15, k + 3, Blocks.air, 3);
		this.setBlock(world, i + 6, j + 15, k + 4, Blocks.air, 3);
		this.setBlock(world, i + 6, j + 15, k + 5, Blocks.air, 3);
		this.setBlock(world, i + 6, j + 15, k + 6, Blocks.air, 3);
		this.setBlock(world, i + 7, j + 0, k + 1, Blocks.cobblestone, 0);
		this.setBlock(world, i + 7, j + 0, k + 2, Blocks.cobblestone, 0);
		this.setBlock(world, i + 7, j + 0, k + 3, Blocks.cobblestone, 0);
		this.setBlock(world, i + 7, j + 0, k + 4, Blocks.cobblestone, 0);
		this.setBlock(world, i + 7, j + 0, k + 5, Blocks.cobblestone, 0);
		this.setBlock(world, i + 7, j + 0, k + 6, Blocks.cobblestone, 0);
		this.setBlock(world, i + 7, j + 3, k + 1, Blocks.planks, 0);
		this.setBlock(world, i + 7, j + 4, k + 1, Blocks.log, 8);
		this.setBlock(world, i + 7, j + 5, k + 1, Blocks.sandstone, 0);
		this.setBlock(world, i + 7, j + 5, k + 2, Blocks.planks, 1);
		this.setBlock(world, i + 7, j + 5, k + 3, Blocks.planks, 1);
		this.setBlock(world, i + 7, j + 5, k + 4, Blocks.planks, 1);
		this.setBlock(world, i + 7, j + 5, k + 5, Blocks.planks, 1);
		this.setBlock(world, i + 7, j + 5, k + 6, Blocks.planks, 1);
		this.setBlock(world, i + 7, j + 6, k + 0, Blocks.air, 3);
		this.setBlock(world, i + 7, j + 6, k + 1, Blocks.planks, 1);
		this.setBlock(world, i + 7, j + 7, k + 1, Blocks.log, 2);
		this.setBlock(world, i + 7, j + 8, k + 1, Blocks.log, 2);
		this.setBlock(world, i + 7, j + 9, k + 1, Blocks.planks, 1);
		this.setBlock(world, i + 7, j + 10, k + 1, Blocks.log, 2);
		this.setBlock(world, i + 7, j + 11, k + 1, Blocks.log, 2);
		this.setBlock(world, i + 7, j + 12, k + 1, Blocks.planks, 1);
		this.setBlock(world, i + 7, j + 12, k + 2, Blocks.planks, 1);
		this.setBlock(world, i + 7, j + 12, k + 3, Blocks.planks, 1);
		this.setBlock(world, i + 7, j + 12, k + 4, Blocks.planks, 1);
		this.setBlock(world, i + 7, j + 12, k + 5, Blocks.planks, 1);
		this.setBlock(world, i + 7, j + 12, k + 6, Blocks.planks, 1);
		this.setBlock(world, i + 7, j + 13, k + 1, Blocks.log, 2);
		this.setBlock(world, i + 7, j + 13, k + 2, Blocks.planks, 1);
		this.setBlock(world, i + 7, j + 13, k + 3, Blocks.planks, 1);
		this.setBlock(world, i + 7, j + 13, k + 4, Blocks.planks, 1);
		this.setBlock(world, i + 7, j + 13, k + 5, Blocks.planks, 1);
		this.setBlock(world, i + 7, j + 13, k + 6, Blocks.planks, 1);
		this.setBlock(world, i + 7, j + 14, k + 0, Blocks.air, 3);
		this.setBlock(world, i + 7, j + 14, k + 1, Blocks.air, 3);
		this.setBlock(world, i + 7, j + 14, k + 2, Blocks.air, 3);
		this.setBlock(world, i + 7, j + 14, k + 3, Blocks.air, 3);
		this.setBlock(world, i + 7, j + 14, k + 4, Blocks.air, 3);
		this.setBlock(world, i + 7, j + 14, k + 5, Blocks.air, 3);
		this.setBlock(world, i + 7, j + 14, k + 6, Blocks.air, 3);
		this.setBlock(world, i + 8, j + 0, k + 1, Blocks.cobblestone, 0);
		this.setBlock(world, i + 8, j + 0, k + 2, Blocks.cobblestone, 0);
		this.setBlock(world, i + 8, j + 0, k + 3, Blocks.cobblestone, 0);
		this.setBlock(world, i + 8, j + 0, k + 4, Blocks.cobblestone, 0);
		this.setBlock(world, i + 8, j + 0, k + 5, Blocks.cobblestone, 0);
		this.setBlock(world, i + 8, j + 0, k + 6, Blocks.cobblestone, 0);
		this.setBlock(world, i + 8, j + 3, k + 1, Blocks.planks, 0);
		this.setBlock(world, i + 8, j + 4, k + 1, Blocks.log, 8);
		this.setBlock(world, i + 8, j + 5, k + 1, Blocks.sandstone, 0);
		this.setBlock(world, i + 8, j + 5, k + 2, Blocks.planks, 1);
		this.setBlock(world, i + 8, j + 5, k + 3, Blocks.planks, 1);
		this.setBlock(world, i + 8, j + 5, k + 4, Blocks.planks, 1);
		this.setBlock(world, i + 8, j + 5, k + 5, Blocks.lit_redstone_lamp, 0);
		this.setBlock(world, i + 8, j + 5, k + 6, Blocks.planks, 1);
		this.setBlock(world, i + 8, j + 6, k + 0, Blocks.air, 3);
		this.setBlock(world, i + 8, j + 6, k + 1, Blocks.planks, 1);
		this.setBlock(world, i + 8, j + 7, k + 1, Blocks.log, 2);
		this.setBlock(world, i + 8, j + 8, k + 1, Blocks.log, 2);
		this.setBlock(world, i + 8, j + 9, k + 1, Blocks.planks, 1);
		this.setBlock(world, i + 8, j + 10, k + 1, Blocks.log, 2);
		this.setBlock(world, i + 8, j + 10, k + 2, Blocks.planks, 1);
		this.setBlock(world, i + 8, j + 10, k + 3, Blocks.planks, 1);
		this.setBlock(world, i + 8, j + 10, k + 4, Blocks.planks, 1);
		this.setBlock(world, i + 8, j + 10, k + 5, Blocks.planks, 1);
		this.setBlock(world, i + 8, j + 10, k + 6, Blocks.planks, 1);
		this.setBlock(world, i + 8, j + 11, k + 1, Blocks.log, 2);
		this.setBlock(world, i + 8, j + 11, k + 2, Blocks.planks, 1);
		this.setBlock(world, i + 8, j + 11, k + 3, Blocks.planks, 1);
		this.setBlock(world, i + 8, j + 11, k + 4, Blocks.planks, 1);
		this.setBlock(world, i + 8, j + 11, k + 5, Blocks.planks, 1);
		this.setBlock(world, i + 8, j + 11, k + 6, Blocks.planks, 1);
		this.setBlock(world, i + 8, j + 12, k + 0, Blocks.air, 3);
		this.setBlock(world, i + 8, j + 12, k + 1, Blocks.air, 3);
		this.setBlock(world, i + 8, j + 12, k + 2, Blocks.air, 3);
		this.setBlock(world, i + 8, j + 12, k + 3, Blocks.air, 3);
		this.setBlock(world, i + 8, j + 12, k + 4, Blocks.air, 3);
		this.setBlock(world, i + 8, j + 12, k + 5, Blocks.air, 3);
		this.setBlock(world, i + 8, j + 12, k + 6, Blocks.air, 3);
		this.setBlock(world, i + 8, j + 13, k + 0, Blocks.air, 3);
		this.setBlock(world, i + 8, j + 13, k + 1, Blocks.air, 3);
		this.setBlock(world, i + 8, j + 13, k + 2, Blocks.air, 3);
		this.setBlock(world, i + 8, j + 13, k + 3, Blocks.air, 3);
		this.setBlock(world, i + 8, j + 13, k + 4, Blocks.air, 3);
		this.setBlock(world, i + 8, j + 13, k + 5, Blocks.air, 3);
		this.setBlock(world, i + 8, j + 13, k + 6, Blocks.air, 3);
		this.setBlock(world, i + 9, j + 0, k + 1, Blocks.cobblestone, 0);
		this.setBlock(world, i + 9, j + 0, k + 2, Blocks.cobblestone, 0);
		this.setBlock(world, i + 9, j + 0, k + 3, Blocks.cobblestone, 0);
		this.setBlock(world, i + 9, j + 0, k + 4, Blocks.cobblestone, 0);
		this.setBlock(world, i + 9, j + 0, k + 5, Blocks.cobblestone, 0);
		this.setBlock(world, i + 9, j + 0, k + 6, Blocks.cobblestone, 0);
		this.setBlock(world, i + 9, j + 1, k + 1, Blocks.sandstone, 0);
		this.setBlock(world, i + 9, j + 2, k + 1, Blocks.planks, 1);
		this.setBlock(world, i + 9, j + 3, k + 1, Blocks.planks, 1);
		this.setBlock(world, i + 9, j + 4, k + 1, Blocks.sandstone, 0);
		this.setBlock(world, i + 9, j + 5, k + 1, Blocks.sandstone, 0);
		this.setBlock(world, i + 9, j + 5, k + 2, Blocks.planks, 1);
		this.setBlock(world, i + 9, j + 5, k + 3, Blocks.planks, 1);
		this.setBlock(world, i + 9, j + 5, k + 4, Blocks.planks, 1);
		this.setBlock(world, i + 9, j + 5, k + 5, Blocks.planks, 1);
		this.setBlock(world, i + 9, j + 5, k + 6, Blocks.planks, 1);
		this.setBlock(world, i + 9, j + 6, k + 0, Blocks.air, 3);
		this.setBlock(world, i + 9, j + 6, k + 1, Blocks.planks, 1);
		this.setBlock(world, i + 9, j + 7, k + 1, Blocks.planks, 1);
		this.setBlock(world, i + 9, j + 8, k + 1, Blocks.planks, 1);
		this.setBlock(world, i + 9, j + 8, k + 2, Blocks.planks, 1);
		this.setBlock(world, i + 9, j + 8, k + 3, Blocks.planks, 1);
		this.setBlock(world, i + 9, j + 8, k + 4, Blocks.planks, 1);
		this.setBlock(world, i + 9, j + 8, k + 5, Blocks.planks, 1);
		this.setBlock(world, i + 9, j + 8, k + 6, Blocks.planks, 1);
		this.setBlock(world, i + 9, j + 9, k + 1, Blocks.planks, 5);
		this.setBlock(world, i + 9, j + 9, k + 2, Blocks.planks, 1);
		this.setBlock(world, i + 9, j + 9, k + 3, Blocks.planks, 1);
		this.setBlock(world, i + 9, j + 9, k + 4, Blocks.planks, 1);
		this.setBlock(world, i + 9, j + 9, k + 5, Blocks.planks, 1);
		this.setBlock(world, i + 9, j + 9, k + 6, Blocks.planks, 1);
		this.setBlock(world, i + 9, j + 10, k + 0, Blocks.air, 3);
		this.setBlock(world, i + 9, j + 10, k + 1, Blocks.air, 3);
		this.setBlock(world, i + 9, j + 10, k + 2, Blocks.air, 3);
		this.setBlock(world, i + 9, j + 10, k + 3, Blocks.air, 3);
		this.setBlock(world, i + 9, j + 10, k + 4, Blocks.air, 3);
		this.setBlock(world, i + 9, j + 10, k + 5, Blocks.air, 3);
		this.setBlock(world, i + 9, j + 10, k + 6, Blocks.air, 3);
		this.setBlock(world, i + 9, j + 11, k + 0, Blocks.air, 3);
		this.setBlock(world, i + 9, j + 11, k + 1, Blocks.air, 3);
		this.setBlock(world, i + 9, j + 11, k + 2, Blocks.air, 3);
		this.setBlock(world, i + 9, j + 11, k + 3, Blocks.air, 3);
		this.setBlock(world, i + 9, j + 11, k + 4, Blocks.air, 3);
		this.setBlock(world, i + 9, j + 11, k + 5, Blocks.air, 3);
		this.setBlock(world, i + 9, j + 11, k + 6, Blocks.air, 3);
		this.setBlock(world, i + 10, j + 0, k + 1, Blocks.cobblestone, 0);
		this.setBlock(world, i + 10, j + 0, k + 2, Blocks.cobblestone, 0);
		this.setBlock(world, i + 10, j + 0, k + 3, Blocks.cobblestone, 0);
		this.setBlock(world, i + 10, j + 0, k + 4, Blocks.cobblestone, 0);
		this.setBlock(world, i + 10, j + 0, k + 5, Blocks.cobblestone, 0);
		this.setBlock(world, i + 10, j + 0, k + 6, Blocks.cobblestone, 0);
		this.setBlock(world, i + 10, j + 1, k + 1, Blocks.sandstone, 0);
		this.setBlock(world, i + 10, j + 2, k + 1, Blocks.air, 12);
		this.setBlock(world, i + 10, j + 3, k + 1, Blocks.air, 12);
		this.setBlock(world, i + 10, j + 4, k + 1, Blocks.sandstone, 0);
		this.setBlock(world, i + 10, j + 5, k + 1, Blocks.sandstone, 0);
		this.setBlock(world, i + 10, j + 5, k + 2, Blocks.planks, 1);
		this.setBlock(world, i + 10, j + 5, k + 3, Blocks.planks, 1);
		this.setBlock(world, i + 10, j + 5, k + 4, Blocks.planks, 1);
		this.setBlock(world, i + 10, j + 5, k + 5, Blocks.planks, 1);
		this.setBlock(world, i + 10, j + 5, k + 6, Blocks.planks, 1);
		this.setBlock(world, i + 10, j + 6, k + 1, Blocks.planks, 1);
		this.setBlock(world, i + 10, j + 6, k + 2, Blocks.planks, 1);
		this.setBlock(world, i + 10, j + 6, k + 3, Blocks.planks, 1);
		this.setBlock(world, i + 10, j + 6, k + 4, Blocks.planks, 1);
		this.setBlock(world, i + 10, j + 6, k + 5, Blocks.planks, 1);
		this.setBlock(world, i + 10, j + 6, k + 6, Blocks.planks, 1);
		this.setBlock(world, i + 10, j + 7, k + 1, Blocks.log, 2);
		this.setBlock(world, i + 10, j + 7, k + 2, Blocks.planks, 1);
		this.setBlock(world, i + 10, j + 7, k + 3, Blocks.planks, 1);
		this.setBlock(world, i + 10, j + 7, k + 4, Blocks.planks, 1);
		this.setBlock(world, i + 10, j + 7, k + 5, Blocks.planks, 1);
		this.setBlock(world, i + 10, j + 7, k + 6, Blocks.planks, 1);
		this.setBlock(world, i + 10, j + 8, k + 0, Blocks.air, 3);
		this.setBlock(world, i + 10, j + 8, k + 1, Blocks.air, 3);
		this.setBlock(world, i + 10, j + 8, k + 2, Blocks.air, 3);
		this.setBlock(world, i + 10, j + 8, k + 3, Blocks.air, 3);
		this.setBlock(world, i + 10, j + 8, k + 4, Blocks.air, 3);
		this.setBlock(world, i + 10, j + 8, k + 5, Blocks.air, 3);
		this.setBlock(world, i + 10, j + 8, k + 6, Blocks.air, 3);
		this.setBlock(world, i + 10, j + 9, k + 0, Blocks.air, 3);
		this.setBlock(world, i + 10, j + 9, k + 1, Blocks.air, 3);
		this.setBlock(world, i + 10, j + 9, k + 2, Blocks.air, 3);
		this.setBlock(world, i + 10, j + 9, k + 3, Blocks.air, 3);
		this.setBlock(world, i + 10, j + 9, k + 4, Blocks.air, 3);
		this.setBlock(world, i + 10, j + 9, k + 5, Blocks.air, 3);
		this.setBlock(world, i + 10, j + 9, k + 6, Blocks.air, 3);
		this.setBlock(world, i + 11, j + 0, k + 1, Blocks.cobblestone, 0);
		this.setBlock(world, i + 11, j + 0, k + 2, Blocks.cobblestone, 0);
		this.setBlock(world, i + 11, j + 0, k + 3, Blocks.cobblestone, 0);
		this.setBlock(world, i + 11, j + 0, k + 4, Blocks.cobblestone, 0);
		this.setBlock(world, i + 11, j + 0, k + 5, Blocks.cobblestone, 0);
		this.setBlock(world, i + 11, j + 0, k + 6, Blocks.cobblestone, 0);
		this.setBlock(world, i + 11, j + 1, k + 1, Blocks.sandstone, 0);
		this.setBlock(world, i + 11, j + 1, k + 2, Blocks.sandstone, 0);
		this.setBlock(world, i + 11, j + 1, k + 3, Blocks.sandstone, 0);
		this.setBlock(world, i + 11, j + 1, k + 4, Blocks.sandstone, 0);
		this.setBlock(world, i + 11, j + 1, k + 5, Blocks.sandstone, 0);
		this.setBlock(world, i + 11, j + 1, k + 6, Blocks.sandstone, 0);
		this.setBlock(world, i + 11, j + 2, k + 1, Blocks.sandstone, 0);
		this.setBlock(world, i + 11, j + 2, k + 2, Blocks.sandstone, 0);
		this.setBlock(world, i + 11, j + 2, k + 3, Blocks.sandstone, 0);
		this.setBlock(world, i + 11, j + 2, k + 4, Blocks.sandstone, 0);
		this.setBlock(world, i + 11, j + 2, k + 5, Blocks.sandstone, 0);
		this.setBlock(world, i + 11, j + 2, k + 6, Blocks.sandstone, 0);
		this.setBlock(world, i + 11, j + 3, k + 1, Blocks.sandstone, 0);
		this.setBlock(world, i + 11, j + 3, k + 2, Blocks.sandstone, 0);
		this.setBlock(world, i + 11, j + 3, k + 3, Blocks.sandstone, 0);
		this.setBlock(world, i + 11, j + 3, k + 4, Blocks.sandstone, 0);
		this.setBlock(world, i + 11, j + 3, k + 5, Blocks.sandstone, 0);
		this.setBlock(world, i + 11, j + 3, k + 6, Blocks.sandstone, 0);
		this.setBlock(world, i + 11, j + 4, k + 1, Blocks.sandstone, 0);
		this.setBlock(world, i + 11, j + 4, k + 2, Blocks.sandstone, 0);
		this.setBlock(world, i + 11, j + 4, k + 3, Blocks.sandstone, 0);
		this.setBlock(world, i + 11, j + 4, k + 4, Blocks.sandstone, 0);
		this.setBlock(world, i + 11, j + 4, k + 5, Blocks.sandstone, 0);
		this.setBlock(world, i + 11, j + 4, k + 6, Blocks.sandstone, 0);
		this.setBlock(world, i + 11, j + 5, k + 1, Blocks.sandstone, 0);
		this.setBlock(world, i + 11, j + 5, k + 2, Blocks.sandstone, 0);
		this.setBlock(world, i + 11, j + 5, k + 3, Blocks.sandstone, 0);
		this.setBlock(world, i + 11, j + 5, k + 4, Blocks.sandstone, 0);
		this.setBlock(world, i + 11, j + 5, k + 5, Blocks.sandstone, 0);
		this.setBlock(world, i + 11, j + 5, k + 6, Blocks.sandstone, 0);
		this.setBlock(world, i + 11, j + 6, k + 0, Blocks.air, 3);
		this.setBlock(world, i + 11, j + 6, k + 1, Blocks.air, 3);
		this.setBlock(world, i + 11, j + 6, k + 2, Blocks.air, 3);
		this.setBlock(world, i + 11, j + 6, k + 3, Blocks.air, 3);
		this.setBlock(world, i + 11, j + 6, k + 4, Blocks.air, 3);
		this.setBlock(world, i + 11, j + 6, k + 5, Blocks.air, 3);
		this.setBlock(world, i + 11, j + 6, k + 6, Blocks.air, 3);
		this.setBlock(world, i + 11, j + 7, k + 0, Blocks.air, 3);
		this.setBlock(world, i + 11, j + 7, k + 1, Blocks.air, 3);
		this.setBlock(world, i + 11, j + 7, k + 2, Blocks.air, 3);
		this.setBlock(world, i + 11, j + 7, k + 3, Blocks.air, 3);
		this.setBlock(world, i + 11, j + 7, k + 4, Blocks.air, 3);
		this.setBlock(world, i + 11, j + 7, k + 5, Blocks.air, 3);
		this.setBlock(world, i + 11, j + 7, k + 6, Blocks.air, 3);
		this.setBlock(world, i + 12, j + 4, k + 0, Blocks.air, 3);
		this.setBlock(world, i + 12, j + 4, k + 1, Blocks.air, 3);
		this.setBlock(world, i + 12, j + 4, k + 2, Blocks.air, 3);
		this.setBlock(world, i + 12, j + 4, k + 3, Blocks.air, 3);
		this.setBlock(world, i + 12, j + 4, k + 4, Blocks.air, 3);
		this.setBlock(world, i + 12, j + 4, k + 5, Blocks.air, 3);
		this.setBlock(world, i + 12, j + 4, k + 6, Blocks.air, 3);
		this.setBlock(world, i + 12, j + 5, k + 0, Blocks.air, 3);
		this.setBlock(world, i + 12, j + 5, k + 1, Blocks.air, 3);
		this.setBlock(world, i + 12, j + 5, k + 2, Blocks.air, 3);
		this.setBlock(world, i + 12, j + 5, k + 3, Blocks.air, 3);
		this.setBlock(world, i + 12, j + 5, k + 4, Blocks.air, 3);
		this.setBlock(world, i + 12, j + 5, k + 5, Blocks.air, 3);
		this.setBlock(world, i + 12, j + 5, k + 6, Blocks.air, 3);
		world.setBlockMetadataWithNotify(i + 3, j + 6, k + 5, 1, 2);
		world.setBlockMetadataWithNotify(i + 4, j + 6, k + 5, 15, 2);
		world.setBlockMetadataWithNotify(i + 7, j + 1, k + 1, 1, 2);
		world.setBlockMetadataWithNotify(i + 7, j + 2, k + 1, 9, 2);
		world.setBlockMetadataWithNotify(i + 8, j + 1, k + 1, 1, 2);
		world.setBlockMetadataWithNotify(i + 8, j + 2, k + 1, 8, 2);
		world.setBlockMetadataWithNotify(i + 8, j + 6, k + 5, 15, 2);
		world.setBlockMetadataWithNotify(i + 9, j + 6, k + 5, 2, 2);

		return true;
	}
}